Workbook
Name Contagem_de_Gender: C̳álculos!#REF!
Name EA_Play_Season_Pass: C̳álculos!$C$15
Name Gender: C̳álculos!$C$35
Name Minecraft__season_Pass_Price: C̳álculos!$C$56
Name Minecraft_Season_Pass_Price: C̳álculos!$C$27
Name SegmentaçãodeDados_Subscription_Type1: #N/A
Name Soma_de_Minecraft_Season_Pass_Price: C̳álculos!#REF!
Name Soma_de_Total_Value: C̳álculos!$C$8

Sheet A̳ssets
B3: Paleta de Cores
B5: # 9BC848 | C5: Xbox Color | E5: # E8E6E9 | F5: negative zone
B6: # 22C55E | C6: Xbox Color
B7: # 2AE6B1 | C7: Menus
B8: # 5BF6A8 | C8: Menus
B12: Logos | J12: ícones

Sheet B̳ases
A1: Subscriber ID | B1: Name | C1: Name2 | D1: Coluna1 | E1: Gender | F1: Plan | G1: Start Date | H1: Auto Renewal | I1: Subscription Price | J1: Subscription Type | K1: EA Play Season Pass | L1: EA Play Season Pass Price | M1: Minecraft Season Pass | N1: Minecraft Season Pass Price | O1: Coupon Value | P1: Total Value | Q1: valor_Liquido
A2: 3231 | B2: João | C2: =_xlfn.CONCAT(B̳ases!$B2," ",B̳ases!$D2) -> João Silva | D2: Silva | E2: Masculino | F2: Ultimate | G2: 45292 | H2: Yes | I2: 15 | J2: Monthly | K2: Yes | L2: 30 | M2: Yes | N2: 20 | O2: 5 | P2: 60 | Q2: =P2-O2 -> 55 | R2: 1
A3: 3232 | B3: Maria | C3: =_xlfn.CONCAT(B̳ases!$B3,B̳ases!$D3) -> MariaOliveira | D3: Oliveira | E3: Feminino | F3: Core | G3: 45306 | H3: No | I3: 5 | J3: Annual | K3: No | M3: No | N3: 0 | O3: 0 | P3: 5 | Q3: =P3-O3 -> 5
A4: 3233 | B4: Lucas | C4: =_xlfn.CONCAT(B̳ases!$B4," ",B̳ases!$D4) -> Lucas Fernandes | D4: Fernandes | E4: Masculino | F4: Standard | G4: 45332 | H4: Yes | I4: 10 | J4: Quarterly | K4: No | M4: Yes | N4: 20 | O4: 10 | P4: 20 | Q4: =P4-O4 -> 10
A5: 3234 | B5: Ana | C5: =_xlfn.CONCAT(B̳ases!$B5,B̳ases!$D5) -> AnaSouza | D5: Souza | E5: Feminino | F5: Ultimate | G5: 45342 | H5: No | I5: 15 | J5: Monthly | K5: Yes | L5: 30 | M5: Yes | N5: 20 | O5: 3 | P5: 62 | Q5: =P5-O5 -> 59
A6: 3235 | B6: Pedro | C6: =_xlfn.CONCAT(B̳ases!$B6," ",B̳ases!$D6) -> Pedro Gonçalves | D6: Gonçalves | E6: Masculino | F6: Core | G6: 45356 | H6: Yes | I6: 5 | J6: Monthly | K6: No | M6: No | N6: 0 | O6: 1 | P6: 4 | Q6: =P6-O6 -> 3
A7: 3236 | B7: Felipe | C7: =_xlfn.CONCAT(B̳ases!$B7," ",B̳ases!$D7) -> Felipe Costa | D7: Costa | E7: Masculino | F7: Standard | G7: 45353 | H7: No | I7: 10 | J7: Monthly | K7: No | M7: Yes | N7: 20 | O7: 2 | P7: 28 | Q7: =P7-O7 -> 26
A8: 3237 | B8: Camila | C8: =_xlfn.CONCAT(B̳ases!$B8,B̳ases!$D8) -> CamilaRibeiro | D8: Ribeiro | E8: Feminino | F8: Ultimate | G8: 45354 | H8: Yes | I8: 15 | J8: Quarterly | K8: Yes | L8: 30 | M8: Yes | N8: 20 | O8: 10 | P8: 55 | Q8: =P8-O8 -> 45
A9: 3238 | B9: André | C9: =_xlfn.CONCAT(B̳ases!$B9," ",B̳ases!$D9) -> André Mendes | D9: Mendes | E9: Masculino | F9: Core | G9: 45355 | H9: Yes | I9: 5 | J9: Annual | K9: No | M9: No | N9: 0 | O9: 0 | P9: 5 | Q9: =P9-O9 -> 5
A10: 3239 | B10: Sofia | C10: =_xlfn.CONCAT(B̳ases!$B10,B̳ases!$D10) -> SofiaAlmeida | D10: Almeida | E10: Feminino | F10: Ultimate | G10: 45356 | H10: No | I10: 15 | J10: Monthly | K10: Yes | L10: 30 | M10: Yes | N10: 20 | O10: 5 | P10: 60 | Q10: =P10-O10 -> 55
A11: 3240 | B11: Bruno | C11: =_xlfn.CONCAT(B̳ases!$B11," ",B̳ases!$D11) -> Bruno Martins | D11: Martins | E11: Masculino | F11: Standard | G11: 45357 | H11: Yes | I11: 10 | J11: Quarterly | K11: No | M11: Yes | N11: 20 | O11: 15 | P11: 15 | Q11: =P11-O11 -> 0
A12: 3241 | B12: Rita | C12: =_xlfn.CONCAT(B̳ases!$B12,B̳ases!$D12) -> RitaCastro | D12: Castro | E12: Feminino | F12: Core | G12: 45358 | H12: No | I12: 5 | J12: Monthly | K12: No | M12: No | N12: 0 | O12: 1 | P12: 4 | Q12: =P12-O12 -> 3
A13: 3242 | B13: Marco | C13: =_xlfn.CONCAT(B̳ases!$B13," ",B̳ases!$D13) -> Marco Túlio | D13: Túlio | E13: Masculino | F13: Ultimate | G13: 45359 | H13: Yes | I13: 15 | J13: Annual | K13: Yes | L13: 30 | M13: Yes | N13: 20 | O13: 20 | P13: 45 | Q13: =P13-O13 -> 25
A14: 3243 | B14: Lívia | C14: =_xlfn.CONCAT(B̳ases!$B14,B̳ases!$D14) -> LíviaSilveira | D14: Silveira | E14: Feminino | F14: Standard | G14: 45360 | H14: No | I14: 10 | J14: Monthly | K14: No | M14: Yes | N14: 20 | O14: 10 | P14: 20 | Q14: =P14-O14 -> 10
A15: 3244 | B15: Diogo | C15: =_xlfn.CONCAT(B̳ases!$B15," ",B̳ases!$D15) -> Diogo Sousa | D15: Sousa | E15: Masculino | F15: Core | G15: 45361 | H15: Yes | I15: 5 | J15: Quarterly | K15: No | M15: No | N15: 0 | O15: 0 | P15: 5 | Q15: =P15-O15 -> 5
A16: 3245 | B16: Fernanda | C16: =_xlfn.CONCAT(B̳ases!$B16,B̳ases!$D16) -> FernandaLima | D16: Lima | E16: Feminino | F16: Ultimate | G16: 45362 | H16: No | I16: 15 | J16: Monthly | K16: Yes | L16: 30 | M16: Yes | N16: 20 | O16: 8 | P16: 57 | Q16: =P16-O16 -> 49
A17: 3246 | B17: Caio | C17: =_xlfn.CONCAT(B̳ases!$B17," ",B̳ases!$D17) -> Caio Pereira | D17: Pereira | E17: Masculino | F17: Standard | G17: 45363 | H17: Yes | I17: 10 | J17: Annual | K17: No | M17: Yes | N17: 20 | O17: 12 | P17: 18 | Q17: =P17-O17 -> 6
A18: 3247 | B18: Beatriz | C18: =_xlfn.CONCAT(B̳ases!$B18," ",B̳ases!$D18) -> Beatriz Gomes | D18: Gomes | E18: Feminino | F18: Core | G18: 45364 | H18: No | I18: 5 | J18: Monthly | K18: No | M18: No | N18: 0 | O18: 2 | P18: 3 | Q18: =P18-O18 -> 1
A19: 3248 | B19: Cesar | C19: =_xlfn.CONCAT(B̳ases!$B19," ",B̳ases!$D19) -> Cesar Oliveira | D19: Oliveira | E19: Masculino | F19: Ultimate | G19: 45365 | H19: Yes | I19: 15 | J19: Quarterly | K19: Yes | L19: 30 | M19: Yes | N19: 20 | O19: 7 | P19: 58 | Q19: =P19-O19 -> 51
A20: 3249 | B20: Débora | C20: =_xlfn.CONCAT(B̳ases!$B20,B̳ases!$D20) -> DéboraMachado | D20: Machado | E20: Feminino | F20: Standard | G20: 45366 | H20: No | I20: 10 | J20: Monthly | K20: No | M20: Yes | N20: 20 | O20: 5 | P20: 25 | Q20: =P20-O20 -> 20
A21: 3250 | B21: Eduardo | C21: =_xlfn.CONCAT(B̳ases!$B21," ",B̳ases!$D21) -> Eduardo Vargas | D21: Vargas | E21: Masculino | F21: Core | G21: 45367 | H21: Yes | I21: 5 | J21: Annual | K21: No | M21: No | N21: 0 | O21: 0 | P21: 5 | Q21: =P21-O21 -> 5
A22: 3251 | B22: Gabriela | C22: =_xlfn.CONCAT(B̳ases!$B22,B̳ases!$D22) -> GabrielaSantos | D22: Santos | E22: Feminino | F22: Ultimate | G22: 45368 | H22: No | I22: 15 | J22: Monthly | K22: Yes | L22: 30 | M22: Yes | N22: 20 | O22: 3 | P22: 62 | Q22: =P22-O22 -> 59
A23: 3252 | B23: Henrique | C23: =_xlfn.CONCAT(B̳ases!$B23," ",B̳ases!$D23) -> Henrique Dias | D23: Dias | E23: Masculino | F23: Standard | G23: 45369 | H23: Yes | I23: 10 | J23: Quarterly | K23: No | M23: Yes | N23: 20 | O23: 15 | P23: 15 | Q23: =P23-O23 -> 0
A24: 3253 | B24: Isabela | C24: =_xlfn.CONCAT(B̳ases!$B24,B̳ases!$D24) -> IsabelaMoreira | D24: Moreira | E24: Feminino | F24: Core | G24: 45370 | H24: No | I24: 5 | J24: Monthly | K24: No | M24: No | N24: 0 | O24: 1 | P24: 4 | Q24: =P24-O24 -> 3
A25: 3254 | B25: Joaquim | C25: =_xlfn.CONCAT(B̳ases!$B25," ",B̳ases!$D25) -> Joaquim Barbosa | D25: Barbosa | E25: Masculino | F25: Ultimate | G25: 45371 | H25: Yes | I25: 15 | J25: Annual | K25: Yes | L25: 30 | M25: Yes | N25: 20 | O25: 20 | P25: 45 | Q25: =P25-O25 -> 25
A26: 3255 | B26: Lara | C26: =_xlfn.CONCAT(B̳ases!$B26,B̳ases!$D26) -> LaraRocha | D26: Rocha | E26: Feminino | F26: Standard | G26: 45372 | H26: No | I26: 10 | J26: Monthly | K26: No | M26: Yes | N26: 20 | O26: 10 | P26: 20 | Q26: =P26-O26 -> 10
A27: 3256 | B27: Matheus | C27: =_xlfn.CONCAT(B̳ases!$B27," ",B̳ases!$D27) -> Matheus Silva | D27: Silva | E27: Masculino | F27: Core | G27: 45373 | H27: Yes | I27: 5 | J27: Quarterly | K27: No | M27: No | N27: 0 | O27: 0 | P27: 5 | Q27: =P27-O27 -> 5
A28: 3257 | B28: Nicole | C28: =_xlfn.CONCAT(B̳ases!$B28," ",B̳ases!$D28) -> Nicole Costa | D28: Costa | E28: Feminino | F28: Ultimate | G28: 45374 | H28: No | I28: 15 | J28: Monthly | K28: Yes | L28: 30 | M28: Yes | N28: 20 | O28: 5 | P28: 60 | Q28: =P28-O28 -> 55
A29: 3258 | B29: Otávio | C29: =_xlfn.CONCAT(B̳ases!$B29," ",B̳ases!$D29) -> Otávio Mendonça | D29: Mendonça | E29: Masculino | F29: Standard | G29: 45375 | H29: Yes | I29: 10 | J29: Annual | K29: No | M29: Yes | N29: 20 | O29: 15 | P29: 15 | Q29: =P29-O29 -> 0
A30: 3259 | B30: Paula | C30: =_xlfn.CONCAT(B̳ases!$B30,B̳ases!$D30) -> PaulaFerreira | D30: Ferreira | E30: Feminino | F30: Core | G30: 45376 | H30: No | I30: 5 | J30: Monthly | K30: No | M30: No | N30: 0 | O30: 1 | P30: 4 | Q30: =P30-O30 -> 3
A31: 3260 | B31: Raquel | C31: =_xlfn.CONCAT(B̳ases!$B31," ",B̳ases!$D31) -> Raquel Alves | D31: Alves | E31: Feminino | F31: Ultimate | G31: 45377 | H31: Yes | I31: 15 | J31: Quarterly | K31: Yes | L31: 30 | M31: Yes | N31: 20 | O31: 7 | P31: 58 | Q31: =P31-O31 -> 51
A32: 3261 | B32: Samuel | C32: =_xlfn.CONCAT(B̳ases!$B32," ",B̳ases!$D32) -> Samuel Pires | D32: Pires | E32: Masculino | F32: Standard | G32: 45378 | H32: No | I32: 10 | J32: Monthly | K32: No | M32: Yes | N32: 20 | O32: 10 | P32: 20 | Q32: =P32-O32 -> 10
A33: 3262 | B33: Tânia | C33: =_xlfn.CONCAT(B̳ases!$B33,B̳ases!$D33) -> TâniaBarros | D33: Barros | E33: Feminino | F33: Core | G33: 45379 | H33: Yes | I33: 5 | J33: Annual | K33: No | M33: No | N33: 0 | O33: 0 | P33: 5 | Q33: =P33-O33 -> 5
A34: 3263 | B34: Vinicius | C34: =_xlfn.CONCAT(B̳ases!$B34," ",B̳ases!$D34) -> Vinicius Lima | D34: Lima | E34: Masculino | F34: Ultimate | G34: 45380 | H34: No | I34: 15 | J34: Monthly | K34: Yes | L34: 30 | M34: Yes | N34: 20 | O34: 3 | P34: 62 | Q34: =P34-O34 -> 59
A35: 3264 | B35: Yasmin | C35: =_xlfn.CONCAT(B̳ases!$B35," ",B̳ases!$D35) -> Yasmin Teixeira | D35: Teixeira | E35: Feminino | F35: Standard | G35: 45381 | H35: Yes | I35: 10 | J35: Quarterly | K35: No | M35: Yes | N35: 20 | O35: 15 | P35: 15 | Q35: =P35-O35 -> 0
A36: 3265 | B36: Zé | C36: =_xlfn.CONCAT(B̳ases!$B36," ",B̳ases!$D36) -> Zé Carlos | D36: Carlos | E36: Masculino | F36: Core | G36: 45382 | H36: No | I36: 5 | J36: Monthly | K36: No | M36: No | N36: 0 | O36: 1 | P36: 4 | Q36: =P36-O36 -> 3
A37: 3266 | B37: Amanda | C37: =_xlfn.CONCAT(B̳ases!$B37,B̳ases!$D37) -> AmandaNogueira | D37: Nogueira | E37: Feminino | F37: Core | G37: 45383 | H37: Yes | I37: 5 | J37: Monthly | K37: No | M37: No | N37: 0 | O37: 0 | P37: 5 | Q37: =P37-O37 -> 5
A38: 3267 | B38: Bruno | C38: =_xlfn.CONCAT(B̳ases!$B38," ",B̳ases!$D38) -> Bruno Cavalheiro | D38: Cavalheiro | E38: Masculino | F38: Ultimate | G38: 45384 | H38: No | I38: 15 | J38: Quarterly | K38: Yes | L38: 30 | M38: Yes | N38: 20 | O38: 7 | P38: 58 | Q38: =P38-O38 -> 51
A39: 3268 | B39: Carla | C39: =_xlfn.CONCAT(B̳ases!$B39,B̳ases!$D39) -> CarlaDias | D39: Dias | E39: Feminino | F39: Standard | G39: 45385 | H39: Yes | I39: 10 | J39: Annual | K39: No | M39: Yes | N39: 20 | O39: 10 | P39: 20 | Q39: =P39-O39 -> 10
A40: 3269 | B40: Diego | C40: =_xlfn.CONCAT(B̳ases!$B40," ",B̳ases!$D40) -> Diego Fontes | D40: Fontes | E40: Masculino | F40: Core | G40: 45386 | H40: No | I40: 5 | J40: Quarterly | K40: No | M40: No | N40: 0 | O40: 1 | P40: 4 | Q40: =P40-O40 -> 3
...

Sheet Planilha1
A1: Subscription Type | B1: All
A3: Rótulos de Linha | B3: Soma de Coupon Value | C3: Soma de Total Value | D3: Soma de Total Value2
A4: Core | B4: 61 | C4: 444 | D4: 444
A5: Standard | B5: 1079 | C5: 1801 | D5: 1801
A6: Ultimate | B6: 982 | C6: 5388 | D6: 5388
A7: Total Geral | B7: 2122 | C7: 7633 | D7: 7633

Sheet C̳álculos
B2: Pergunta de Negócio 1: Qual faturamento Total de vendas de planos anuais (contendo todas as assinaturas agregadas).
B3: Pergunta de Negócio 2: Qual faturamento Total de vendas de planos anuais separado por renovação não é por auto renovação.
B6: Subscription Type | C6: Annual
B8: Rótulos de Linha | C8: Soma de Total Value
B9: No | C9: 217
B10: Yes | C10: 1537
B11: Total Geral | C11: 1754 | D11: =GETPIVOTDATA("[Measures].[Soma de Total Value 3]",$B$8) -> 1754
B13: Pergunta Negócio 3: Total de vendas de assinaturas do EA Play
B15: Subscription Type | C15: Annual
B17: Rótulos de Linha | C17: Soma de EA Play Season Pass Price
B18: Ultimate | C18: 600
B19: Total Geral | C19: 600 | D19: =GETPIVOTDATA("[Measures].[Soma de EA Play Season Pass Price]",$B$17) -> 600
B23: Pergunta Negócio 4: Total de vendas de assinaturas do Season Pass Price
B24: Subscription Type | C24: Annual
B26: Rótulos de Linha | C26: Soma de Minecraft Season Pass Price
B27: Core | C27: 0
B28: Standard | C28: 540
B29: Ultimate | C29: 400
B30: Total Geral | C30: 940 | D30: =GETPIVOTDATA("[Measures].[Soma de Minecraft Season Pass Price]",$B$26) -> 940
B33: Pergunta Negócio 5: Qual genero que mais consome os produtos?
B36: Rótulos de Linha | C36: Contagem de Gender
B37: Feminino | C37: 34
B38: Masculino | C38: 37
B39: Total Geral | C39: 71
B41: Pergunta Negócio 6: Qual o total de descontos, Lucro total e Lucro liquído?
B42: Subscription Type | C42: Annual
B44: Rótulos de Linha | C44: Coupon_Value | D44: Total_Value | E44: Valor_Liquido
B45: Core | C45: 0 | D45: 120 | E45: 120
B46: Standard | C46: 362 | D46: 448 | E46: 86
B47: Ultimate | C47: 114 | D47: 1186 | E47: 1072
B48: Total Geral | C48: 476 | D48: 1754 | E48: 1278
B52: Pergunta Negócio 7: Qual o ticket médio por cliente?
B54: Subscription Type | C54: Annual
B56: Rótulos de Linha | C56: Média de Total Value
B57: Core | C57: 5
B58: Standard | C58: 16.592593
B59: Ultimate | C59: 59.3
B60: Total Geral | C60: 24.704225

Sheet D̳ashboard
D2: XBOX GAME PASS SUBSCRIPTIONS SALES
A4: > Bem vindo, Felipe | C4: Calculation period: 25/03/2025 - 25/03/2026 | Update date: 25/03/2026 15:00:00
